<?xml version="1.0"?>
<robot name="digital_twin_robot">
  <!-- Base Link -->
  <link name="base_link">
    <visual>
      <geometry>
        <box size="0.5 0.5 0.2"/>
      </geometry>
      <material name="blue">
        <color rgba="0 0 1 1"/>
      </material>
    </visual>
    <collision>
      <geometry>
        <box size="0.5 0.5 0.2"/>
      </geometry>
    </collision>
    <inertial>
      <mass value="10.0"/>
      <inertia ixx="0.416" ixy="0.0" ixz="0.0" iyy="0.416" iyz="0.0" izz="0.625"/>
    </inertial>
  </link>

  <!-- Left Wheel -->
  <link name="wheel_left">
    <visual>
      <geometry>
        <cylinder radius="0.1" length="0.05"/>
      </geometry>
      <material name="black">
        <color rgba="0 0 0 1"/>
      </material>
    </visual>
    <collision>
      <geometry>
        <cylinder radius="0.1" length="0.05"/>
      </geometry>
    </collision>
    <inertial>
      <mass value="1.0"/>
      <inertia ixx="0.002916" ixy="0.0" ixz="0.0" iyy="0.002916" iyz="0.0" izz="0.005"/>
    </inertial>
  </link>

  <!-- Right Wheel -->
  <link name="wheel_right">
    <visual>
      <geometry>
        <cylinder radius="0.1" length="0.05"/>
      </geometry>
      <material name="black">
        <color rgba="0 0 0 1"/>
      </material>
    </visual>
    <collision>
      <geometry>
        <cylinder radius="0.1" length="0.05"/>
      </geometry>
    </collision>
    <inertial>
      <mass value="1.0"/>
      <inertia ixx="0.002916" ixy="0.0" ixz="0.0" iyy="0.002916" iyz="0.0" izz="0.005"/>
    </inertial>
  </link>

  <!-- Caster Wheel -->
  <link name="caster_wheel">
    <visual>
      <geometry>
        <sphere radius="0.05"/>
      </geometry>
      <material name="gray">
        <color rgba="0.5 0.5 0.5 1"/>
      </material>
    </visual>
    <collision>
      <geometry>
        <sphere radius="0.05"/>
      </geometry>
    </collision>
    <inertial>
      <mass value="0.5"/>
      <inertia ixx="0.0005" ixy="0.0" ixz="0.0" iyy="0.0005" iyz="0.0" izz="0.0005"/>
    </inertial>
  </link>

  <!-- Base to Left Wheel Joint -->
  <joint name="base_to_wheel_left" type="continuous">
    <parent link="base_link"/>
    <child link="wheel_left"/>
    <origin xyz="0.0 0.25 0.0" rpy="0 0 0"/>
    <axis xyz="0 1 0"/>
  </joint>

  <!-- Base to Right Wheel Joint -->
  <joint name="base_to_wheel_right" type="continuous">
    <parent link="base_link"/>
    <child link="wheel_right"/>
    <origin xyz="0.0 -0.25 0.0" rpy="0 0 0"/>
    <axis xyz="0 1 0"/>
  </joint>

  <!-- Base to Caster Wheel Joint -->
  <joint name="base_to_caster" type="fixed">
    <parent link="base_link"/>
    <child link="caster_wheel"/>
    <origin xyz="0.2 0.0 -0.15" rpy="0 0 0"/>
  </joint>

  <!-- Gazebo plugins for ROS2 control -->
  <gazebo>
    <plugin filename="libgazebo_ros2_control.so" name="gazebo_ros2_control">
      <parameters>$(find digital_twin_examples)/config/diffdrive_controller.yaml</parameters>
    </plugin>
  </gazebo>

  <!-- Gazebo material for links -->
  <gazebo reference="base_link">
    <material>Gazebo/Blue</material>
  </gazebo>
  
  <gazebo reference="wheel_left">
    <material>Gazebo/Black</material>
  </gazebo>
  
  <gazebo reference="wheel_right">
    <material>Gazebo/Black</material>
  </gazebo>
  
  <gazebo reference="caster_wheel">
    <material>Gazebo/Gray</material>
  </gazebo>
</robot>