<?xml version="1.0"?>
<robot name="simple_robot" xmlns:xacro="http://www.ros.org/wiki/xacro">
  <!-- Materials -->
  <material name="blue">
    <color rgba="0.0 0.0 0.8 1.0"/>
  </material>
  <material name="black">
    <color rgba="0.0 0.0 0.0 1.0"/>
  </material>
  <material name="white">
    <color rgba="1.0 1.0 1.0 1.0"/>
  </material>
  
  <!-- Base Link -->
  <link name="base_link">
    <visual>
      <geometry>
        <cylinder length="0.2" radius="0.2"/>
      </geometry>
      <material name="blue"/>
      <origin xyz="0 0 0" rpy="0 0 0"/>
    </visual>
    
    <collision>
      <geometry>
        <cylinder length="0.2" radius="0.2"/>
      </geometry>
      <origin xyz="0 0 0" rpy="0 0 0"/>
    </collision>
    
    <inertial>
      <mass value="1.0"/>
      <inertia 
        ixx="0.01" ixy="0.0" ixz="0.0"
        iyy="0.01" iyz="0.0"
        izz="0.02"/>
    </inertial>
  </link>
  
  <!-- Left Wheel -->
  <joint name="left_wheel_joint" type="continuous">
    <parent link="base_link"/>
    <child link="left_wheel"/>
    <origin xyz="0 0.15 -0.05" rpy="0 0 0"/>
    <axis xyz="0 1 0"/>
  </joint>
  
  <link name="left_wheel">
    <visual>
      <geometry>
        <cylinder length="0.05" radius="0.1"/>
      </geometry>
      <material name="black"/>
      <origin xyz="0 0 0" rpy="1.5708 0 0"/>
    </visual>
    
    <collision>
      <geometry>
        <cylinder length="0.05" radius="0.1"/>
      </geometry>
      <origin xyz="0 0 0" rpy="1.5708 0 0"/>
    </collision>
    
    <inertial>
      <mass value="0.2"/>
      <inertia 
        ixx="0.001" ixy="0.0" ixz="0.0"
        iyy="0.001" iyz="0.0"
        izz="0.002"/>
    </inertial>
  </link>
  
  <!-- Right Wheel -->
  <joint name="right_wheel_joint" type="continuous">
    <parent link="base_link"/>
    <child link="right_wheel"/>
    <origin xyz="0 -0.15 -0.05" rpy="0 0 0"/>
    <axis xyz="0 1 0"/>
  </joint>
  
  <link name="right_wheel">
    <visual>
      <geometry>
        <cylinder length="0.05" radius="0.1"/>
      </geometry>
      <material name="black"/>
      <origin xyz="0 0 0" rpy="1.5708 0 0"/>
    </visual>
    
    <collision>
      <geometry>
        <cylinder length="0.05" radius="0.1"/>
      </geometry>
      <origin xyz="0 0 0" rpy="1.5708 0 0"/>
    </collision>
    
    <inertial>
      <mass value="0.2"/>
      <inertia 
        ixx="0.001" ixy="0.0" ixz="0.0"
        iyy="0.001" iyz="0.0"
        izz="0.002"/>
    </inertial>
  </link>
  
  <!-- caster wheel -->
  <joint name="caster_joint" type="fixed">
    <parent link="base_link"/>
    <child link="caster"/>
    <origin xyz="-0.15 0 -0.05" rpy="0 0 0"/>
  </joint>
  
  <link name="caster">
    <visual>
      <geometry>
        <sphere radius="0.05"/>
      </geometry>
      <material name="white"/>
    </visual>
    
    <collision>
      <geometry>
        <sphere radius="0.05"/>
      </geometry>
    </collision>
    
    <inertial>
      <mass value="0.1"/>
      <inertia 
        ixx="0.001" ixy="0.0" ixz="0.0"
        iyy="0.001" iyz="0.0"
        izz="0.001"/>
    </inertial>
  </link>
</robot>